
-----------------------------------------
正在处理dapp：bZx.json~
address list = {'0xb983e01458529665007ff7e0cddecdb74b967eb6'}
0xb983e01458529665007ff7e0cddecdb74b967eb6获取的源代码为空！

-----------------------------------------
bZx.json已经处理完成！

['DODO.json', 'FEGtoken.json', 'FormationFi.json', 'Hegic.json', 'InverseFinance.json', 'JAY.json', 'LiFi.json', 'MerlinLab.json', 'MonoX.json', 'NBANFT.json', 'Nmbplatform.json', 'PancakeHunny.json', 'PopsicleFinance.json', 'PunkProtocol.json', 'QubitFinance.json', 'RevestFinance.json', 'RikkeiFinance.json', 'SaddleFinance.json', 'SashimiSwap.json', 'Soda.json', 'SpaceGodzilla.json', 'SushiSwap.json', 'UmbrellaNetwork.json', 'UraniumFinance.json', 'VisorFinance.json', 'WaultFinance.json', 'WildCredit.json', 'XCarnival.json']

-----------------------------------------
正在处理dapp：FEGtoken.json~
address list = {'0x818e2013dd7d9bf4547aaabf6b617c1262578bc7', '0x9a843bb125a3c03f496cb44653741f2cef82f445'}
0x818e2013dd7d9bf4547aaabf6b617c1262578bc7获取的源代码为空！
0x9a843bb125a3c03f496cb44653741f2cef82f445获取的源代码为空！

-----------------------------------------
FEGtoken.json已经处理完成！

['DODO.json', 'FormationFi.json', 'Hegic.json', 'InverseFinance.json', 'JAY.json', 'LiFi.json', 'MerlinLab.json', 'MonoX.json', 'NBANFT.json', 'Nmbplatform.json', 'PancakeHunny.json', 'PopsicleFinance.json', 'PunkProtocol.json', 'QubitFinance.json', 'RevestFinance.json', 'RikkeiFinance.json', 'SaddleFinance.json', 'SashimiSwap.json', 'Soda.json', 'SpaceGodzilla.json', 'SushiSwap.json', 'UmbrellaNetwork.json', 'UraniumFinance.json', 'VisorFinance.json', 'WaultFinance.json', 'WildCredit.json', 'XCarnival.json']

-----------------------------------------
正在处理dapp：Hegic.json~
address list = {'0xd05a937a54ffd66c065ac053091d1aca6a334b39', '0xedf3b24db6b1b571f3773dd311fd8b0af7abb938', '0x34ddc40e17bc8f0a159ba4fc297e55bd3f7c75aa'}
0xd05a937a54ffd66c065ac053091d1aca6a334b39获取的源代码为空！
0xedf3b24db6b1b571f3773dd311fd8b0af7abb938获取的源代码为空！
0x34ddc40e17bc8f0a159ba4fc297e55bd3f7c75aa获取的源代码为空！

-----------------------------------------
Hegic.json已经处理完成！

['DODO.json', 'FormationFi.json', 'InverseFinance.json', 'JAY.json', 'LiFi.json', 'MerlinLab.json', 'MonoX.json', 'NBANFT.json', 'Nmbplatform.json', 'PancakeHunny.json', 'PopsicleFinance.json', 'PunkProtocol.json', 'QubitFinance.json', 'RevestFinance.json', 'RikkeiFinance.json', 'SaddleFinance.json', 'SashimiSwap.json', 'Soda.json', 'SpaceGodzilla.json', 'SushiSwap.json', 'UmbrellaNetwork.json', 'UraniumFinance.json', 'VisorFinance.json', 'WaultFinance.json', 'WildCredit.json', 'XCarnival.json']

-----------------------------------------
正在处理dapp：JAY.json~


--- 异常信息 ---
Traceback (most recent call last):
  File "D:\anaconda3\envs\pytorch\Lib\site-packages\urllib3\connectionpool.py", line 711, in urlopen
    self._prepare_proxy(conn)
  File "D:\anaconda3\envs\pytorch\Lib\site-packages\urllib3\connectionpool.py", line 1007, in _prepare_proxy
    conn.connect()
  File "D:\anaconda3\envs\pytorch\Lib\site-packages\urllib3\connection.py", line 419, in connect
    self.sock = ssl_wrap_socket(
                ^^^^^^^^^^^^^^^^
  File "D:\anaconda3\envs\pytorch\Lib\site-packages\urllib3\util\ssl_.py", line 449, in ssl_wrap_socket
    ssl_sock = _ssl_wrap_socket_impl(
               ^^^^^^^^^^^^^^^^^^^^^^
  File "D:\anaconda3\envs\pytorch\Lib\site-packages\urllib3\util\ssl_.py", line 493, in _ssl_wrap_socket_impl
    return ssl_context.wrap_socket(sock, server_hostname=server_hostname)
           ^^^^^^^^^^^^^^^^^^^^^^^^^^^^^^^^^^^^^^^^^^^^^^^^^^^^^^^^^^^^^^
  File "D:\anaconda3\envs\pytorch\Lib\ssl.py", line 517, in wrap_socket
    return self.sslsocket_class._create(
           ^^^^^^^^^^^^^^^^^^^^^^^^^^^^^
  File "D:\anaconda3\envs\pytorch\Lib\ssl.py", line 1075, in _create
    self.do_handshake()
  File "D:\anaconda3\envs\pytorch\Lib\ssl.py", line 1346, in do_handshake
    self._sslobj.do_handshake()
ConnectionAbortedError: [WinError 10053] 你的主机中的软件中止了一个已建立的连接。

During handling of the above exception, another exception occurred:

Traceback (most recent call last):
  File "D:\anaconda3\envs\pytorch\Lib\site-packages\requests\adapters.py", line 486, in send
    resp = conn.urlopen(
           ^^^^^^^^^^^^^
  File "D:\anaconda3\envs\pytorch\Lib\site-packages\urllib3\connectionpool.py", line 798, in urlopen
    retries = retries.increment(
              ^^^^^^^^^^^^^^^^^^
  File "D:\anaconda3\envs\pytorch\Lib\site-packages\urllib3\util\retry.py", line 592, in increment
    raise MaxRetryError(_pool, url, error or ResponseError(cause))
urllib3.exceptions.MaxRetryError: HTTPSConnectionPool(host='api.etherscan.io', port=443): Max retries exceeded with url: /api?module=proxy&action=eth_getTransactionReceipt&txhash=0x18f04d457b9876ff5868b12724b93abd8b4dc4160f1ac7f416ee5de1cade8abd&apikey=4QP6SY9V7XXDJDEJBGC1NAI3KXRIU5CDEE (Caused by ProxyError('Cannot connect to proxy.', ConnectionAbortedError(10053, '你的主机中的软件中止了一个已建立的连接。', None, 10053, None)))

During handling of the above exception, another exception occurred:

Traceback (most recent call last):
  File "D:\python\PycharmCodes\RAG\code_process.py", line 164, in <module>
    asyncio.run(handler.process(file))
  File "D:\anaconda3\envs\pytorch\Lib\asyncio\runners.py", line 190, in run
    return runner.run(main)
           ^^^^^^^^^^^^^^^^
  File "D:\anaconda3\envs\pytorch\Lib\asyncio\runners.py", line 118, in run
    return self._loop.run_until_complete(task)
           ^^^^^^^^^^^^^^^^^^^^^^^^^^^^^^^^^^^
  File "D:\anaconda3\envs\pytorch\Lib\asyncio\base_events.py", line 653, in run_until_complete
    return future.result()
           ^^^^^^^^^^^^^^^
  File "D:\python\PycharmCodes\RAG\code_process.py", line 67, in process
    address = get_contract_address_from_tx(_hash, _platform)
              ^^^^^^^^^^^^^^^^^^^^^^^^^^^^^^^^^^^^^^^^^^^^^^
  File "D:\python\PycharmCodes\RAG\get_source_code.py", line 27, in get_contract_address_from_tx
    response = requests.get(url)
               ^^^^^^^^^^^^^^^^^
  File "D:\anaconda3\envs\pytorch\Lib\site-packages\requests\api.py", line 73, in get
    return request("get", url, params=params, **kwargs)
           ^^^^^^^^^^^^^^^^^^^^^^^^^^^^^^^^^^^^^^^^^^^^
  File "D:\anaconda3\envs\pytorch\Lib\site-packages\requests\api.py", line 59, in request
    return session.request(method=method, url=url, **kwargs)
           ^^^^^^^^^^^^^^^^^^^^^^^^^^^^^^^^^^^^^^^^^^^^^^^^^
  File "D:\anaconda3\envs\pytorch\Lib\site-packages\requests\sessions.py", line 589, in request
    resp = self.send(prep, **send_kwargs)
           ^^^^^^^^^^^^^^^^^^^^^^^^^^^^^^
  File "D:\anaconda3\envs\pytorch\Lib\site-packages\requests\sessions.py", line 703, in send
    r = adapter.send(request, **kwargs)
        ^^^^^^^^^^^^^^^^^^^^^^^^^^^^^^^
  File "D:\anaconda3\envs\pytorch\Lib\site-packages\requests\adapters.py", line 513, in send
    raise ProxyError(e, request=request)
requests.exceptions.ProxyError: HTTPSConnectionPool(host='api.etherscan.io', port=443): Max retries exceeded with url: /api?module=proxy&action=eth_getTransactionReceipt&txhash=0x18f04d457b9876ff5868b12724b93abd8b4dc4160f1ac7f416ee5de1cade8abd&apikey=4QP6SY9V7XXDJDEJBGC1NAI3KXRIU5CDEE (Caused by ProxyError('Cannot connect to proxy.', ConnectionAbortedError(10053, '你的主机中的软件中止了一个已建立的连接。', None, 10053, None)))
