
-----------------------------------------
正在处理dapp：DODO.json~
address list = {'0xa356867fdcea8e71aeaf87805808803806231fdc', '0xa57bd00134b2850b2a1c55860c9e9ea100fdd6cf', '0xb2b551ced82fab96d60be210620c26cf83fcd727', '0x00000000e84f2bbdfb129ed6e495c7f879f3e634', '0xa2cb66ebb947d217f61510882096f6e95c1de97d', '0xdef1c0ded9bec7f1a1670819833240f027b25eff', '0x111111125434b319222cdbf8c261674adb56f3ae'}
0xa356867fdcea8e71aeaf87805808803806231fdc获取的源代码为空！
0xa57bd00134b2850b2a1c55860c9e9ea100fdd6cf获取的源代码为空！
0xb2b551ced82fab96d60be210620c26cf83fcd727获取的源代码为空！
0x00000000e84f2bbdfb129ed6e495c7f879f3e634获取的源代码为空！
0xa2cb66ebb947d217f61510882096f6e95c1de97d获取的源代码为空！
0x111111125434b319222cdbf8c261674adb56f3ae获取的源代码为空！

-----------------------------------------
DODO.json已经处理完成！

['FormationFi.json', 'InverseFinance.json', 'JAY.json', 'LiFi.json', 'MerlinLab.json', 'MonoX.json', 'NBANFT.json', 'Nmbplatform.json', 'PancakeHunny.json', 'PopsicleFinance.json', 'PunkProtocol.json', 'QubitFinance.json', 'RevestFinance.json', 'RikkeiFinance.json', 'SaddleFinance.json', 'SashimiSwap.json', 'Soda.json', 'SpaceGodzilla.json', 'SushiSwap.json', 'UmbrellaNetwork.json', 'UraniumFinance.json', 'VisorFinance.json', 'WaultFinance.json', 'WildCredit.json', 'XCarnival.json']

-----------------------------------------
正在处理dapp：InverseFinance.json~
address list = {'0xbeccb6bb0aa4ab551966a7e4b97cec74bb359bf6', '0xf508c58ce37ce40a40997c715075172691f92e2d'}
0xbeccb6bb0aa4ab551966a7e4b97cec74bb359bf6编译结果 ast 为空
0xf508c58ce37ce40a40997c715075172691f92e2d获取的源代码为空！

-----------------------------------------
InverseFinance.json已经处理完成！

['FormationFi.json', 'JAY.json', 'LiFi.json', 'MerlinLab.json', 'MonoX.json', 'NBANFT.json', 'Nmbplatform.json', 'PancakeHunny.json', 'PopsicleFinance.json', 'PunkProtocol.json', 'QubitFinance.json', 'RevestFinance.json', 'RikkeiFinance.json', 'SaddleFinance.json', 'SashimiSwap.json', 'Soda.json', 'SpaceGodzilla.json', 'SushiSwap.json', 'UmbrellaNetwork.json', 'UraniumFinance.json', 'VisorFinance.json', 'WaultFinance.json', 'WildCredit.json', 'XCarnival.json']

-----------------------------------------
正在处理dapp：LiFi.json~


--- 异常信息 ---
Traceback (most recent call last):
  File "D:\anaconda3\envs\pytorch\Lib\site-packages\urllib3\connectionpool.py", line 711, in urlopen
    self._prepare_proxy(conn)
  File "D:\anaconda3\envs\pytorch\Lib\site-packages\urllib3\connectionpool.py", line 1007, in _prepare_proxy
    conn.connect()
  File "D:\anaconda3\envs\pytorch\Lib\site-packages\urllib3\connection.py", line 419, in connect
    self.sock = ssl_wrap_socket(
                ^^^^^^^^^^^^^^^^
  File "D:\anaconda3\envs\pytorch\Lib\site-packages\urllib3\util\ssl_.py", line 449, in ssl_wrap_socket
    ssl_sock = _ssl_wrap_socket_impl(
               ^^^^^^^^^^^^^^^^^^^^^^
  File "D:\anaconda3\envs\pytorch\Lib\site-packages\urllib3\util\ssl_.py", line 493, in _ssl_wrap_socket_impl
    return ssl_context.wrap_socket(sock, server_hostname=server_hostname)
           ^^^^^^^^^^^^^^^^^^^^^^^^^^^^^^^^^^^^^^^^^^^^^^^^^^^^^^^^^^^^^^
  File "D:\anaconda3\envs\pytorch\Lib\ssl.py", line 517, in wrap_socket
    return self.sslsocket_class._create(
           ^^^^^^^^^^^^^^^^^^^^^^^^^^^^^
  File "D:\anaconda3\envs\pytorch\Lib\ssl.py", line 1075, in _create
    self.do_handshake()
  File "D:\anaconda3\envs\pytorch\Lib\ssl.py", line 1346, in do_handshake
    self._sslobj.do_handshake()
ConnectionAbortedError: [WinError 10053] 你的主机中的软件中止了一个已建立的连接。

During handling of the above exception, another exception occurred:

Traceback (most recent call last):
  File "D:\anaconda3\envs\pytorch\Lib\site-packages\requests\adapters.py", line 486, in send
    resp = conn.urlopen(
           ^^^^^^^^^^^^^
  File "D:\anaconda3\envs\pytorch\Lib\site-packages\urllib3\connectionpool.py", line 798, in urlopen
    retries = retries.increment(
              ^^^^^^^^^^^^^^^^^^
  File "D:\anaconda3\envs\pytorch\Lib\site-packages\urllib3\util\retry.py", line 592, in increment
    raise MaxRetryError(_pool, url, error or ResponseError(cause))
urllib3.exceptions.MaxRetryError: HTTPSConnectionPool(host='api.etherscan.io', port=443): Max retries exceeded with url: /api?module=proxy&action=eth_getTransactionReceipt&txhash=0xc9ab03e607e0e1f31f8d5c40f7029f28ad76db511877775941d4262e8800e3d7&apikey=4QP6SY9V7XXDJDEJBGC1NAI3KXRIU5CDEE (Caused by ProxyError('Cannot connect to proxy.', ConnectionAbortedError(10053, '你的主机中的软件中止了一个已建立的连接。', None, 10053, None)))

During handling of the above exception, another exception occurred:

Traceback (most recent call last):
  File "D:\python\PycharmCodes\RAG\code_process.py", line 164, in <module>
    asyncio.run(handler.process(file))
  File "D:\anaconda3\envs\pytorch\Lib\asyncio\runners.py", line 190, in run
    return runner.run(main)
           ^^^^^^^^^^^^^^^^
  File "D:\anaconda3\envs\pytorch\Lib\asyncio\runners.py", line 118, in run
    return self._loop.run_until_complete(task)
           ^^^^^^^^^^^^^^^^^^^^^^^^^^^^^^^^^^^
  File "D:\anaconda3\envs\pytorch\Lib\asyncio\base_events.py", line 653, in run_until_complete
    return future.result()
           ^^^^^^^^^^^^^^^
  File "D:\python\PycharmCodes\RAG\code_process.py", line 67, in process
    address = get_contract_address_from_tx(_hash, _platform)
              ^^^^^^^^^^^^^^^^^^^^^^^^^^^^^^^^^^^^^^^^^^^^^^
  File "D:\python\PycharmCodes\RAG\get_source_code.py", line 27, in get_contract_address_from_tx
    response = requests.get(url)
               ^^^^^^^^^^^^^^^^^
  File "D:\anaconda3\envs\pytorch\Lib\site-packages\requests\api.py", line 73, in get
    return request("get", url, params=params, **kwargs)
           ^^^^^^^^^^^^^^^^^^^^^^^^^^^^^^^^^^^^^^^^^^^^
  File "D:\anaconda3\envs\pytorch\Lib\site-packages\requests\api.py", line 59, in request
    return session.request(method=method, url=url, **kwargs)
           ^^^^^^^^^^^^^^^^^^^^^^^^^^^^^^^^^^^^^^^^^^^^^^^^^
  File "D:\anaconda3\envs\pytorch\Lib\site-packages\requests\sessions.py", line 589, in request
    resp = self.send(prep, **send_kwargs)
           ^^^^^^^^^^^^^^^^^^^^^^^^^^^^^^
  File "D:\anaconda3\envs\pytorch\Lib\site-packages\requests\sessions.py", line 703, in send
    r = adapter.send(request, **kwargs)
        ^^^^^^^^^^^^^^^^^^^^^^^^^^^^^^^
  File "D:\anaconda3\envs\pytorch\Lib\site-packages\requests\adapters.py", line 513, in send
    raise ProxyError(e, request=request)
requests.exceptions.ProxyError: HTTPSConnectionPool(host='api.etherscan.io', port=443): Max retries exceeded with url: /api?module=proxy&action=eth_getTransactionReceipt&txhash=0xc9ab03e607e0e1f31f8d5c40f7029f28ad76db511877775941d4262e8800e3d7&apikey=4QP6SY9V7XXDJDEJBGC1NAI3KXRIU5CDEE (Caused by ProxyError('Cannot connect to proxy.', ConnectionAbortedError(10053, '你的主机中的软件中止了一个已建立的连接。', None, 10053, None)))
