
-----------------------------------------
正在处理dapp：MerlinLab.json~
address list = {'0x1509e9df7fd7f567f6e52bcada0035932281cd0d', '0xeb69bad9662fbe068e851540778d845e41cd0f54', '0xfeffa88e6e3c99937b73faa6f7a770f20b661cbe', '0xcc369faf26c0457ceea7a24bbfe158e106214147', '0x25ed360a850838fcedd0a881b8962efecf5ffcbc'}
0x1509e9df7fd7f567f6e52bcada0035932281cd0d获取的源代码为空！
0xeb69bad9662fbe068e851540778d845e41cd0f54获取的源代码为空！
0xfeffa88e6e3c99937b73faa6f7a770f20b661cbe获取的源代码为空！
0xcc369faf26c0457ceea7a24bbfe158e106214147获取的源代码为空！
0x25ed360a850838fcedd0a881b8962efecf5ffcbc获取的源代码为空！

-----------------------------------------
MerlinLab.json已经处理完成！

['MonoX.json', 'NBANFT.json', 'Nmbplatform.json', 'PancakeHunny.json', 'PopsicleFinance.json', 'PunkProtocol.json', 'QubitFinance.json', 'RevestFinance.json', 'RikkeiFinance.json', 'SaddleFinance.json', 'SashimiSwap.json', 'Soda.json', 'SpaceGodzilla.json', 'SushiSwap.json', 'UmbrellaNetwork.json', 'UraniumFinance.json', 'VisorFinance.json', 'WaultFinance.json', 'WildCredit.json', 'XCarnival.json']

-----------------------------------------
正在处理dapp：NBANFT.json~
address list = {'0xdd5a649fc076886dfd4b9ad6acfc9b5eb882e83c'}
0xdd5a649fc076886dfd4b9ad6acfc9b5eb882e83c编译结果 ast 为空

-----------------------------------------
NBANFT.json已经处理完成！

['MonoX.json', 'Nmbplatform.json', 'PancakeHunny.json', 'PopsicleFinance.json', 'PunkProtocol.json', 'QubitFinance.json', 'RevestFinance.json', 'RikkeiFinance.json', 'SaddleFinance.json', 'SashimiSwap.json', 'Soda.json', 'SpaceGodzilla.json', 'SushiSwap.json', 'UmbrellaNetwork.json', 'UraniumFinance.json', 'VisorFinance.json', 'WaultFinance.json', 'WildCredit.json', 'XCarnival.json']

-----------------------------------------
正在处理dapp：PancakeHunny.json~
address list = {'0xb9b0090aaa81f374d66d94a8138d80caa2002950', '0x109ea28dbdea5e6ec126fbc8c33845dfe812a300'}


--- 异常信息 ---
Traceback (most recent call last):
  File "D:\anaconda3\envs\pytorch\Lib\site-packages\urllib3\connectionpool.py", line 711, in urlopen
    self._prepare_proxy(conn)
  File "D:\anaconda3\envs\pytorch\Lib\site-packages\urllib3\connectionpool.py", line 1007, in _prepare_proxy
    conn.connect()
  File "D:\anaconda3\envs\pytorch\Lib\site-packages\urllib3\connection.py", line 419, in connect
    self.sock = ssl_wrap_socket(
                ^^^^^^^^^^^^^^^^
  File "D:\anaconda3\envs\pytorch\Lib\site-packages\urllib3\util\ssl_.py", line 449, in ssl_wrap_socket
    ssl_sock = _ssl_wrap_socket_impl(
               ^^^^^^^^^^^^^^^^^^^^^^
  File "D:\anaconda3\envs\pytorch\Lib\site-packages\urllib3\util\ssl_.py", line 493, in _ssl_wrap_socket_impl
    return ssl_context.wrap_socket(sock, server_hostname=server_hostname)
           ^^^^^^^^^^^^^^^^^^^^^^^^^^^^^^^^^^^^^^^^^^^^^^^^^^^^^^^^^^^^^^
  File "D:\anaconda3\envs\pytorch\Lib\ssl.py", line 517, in wrap_socket
    return self.sslsocket_class._create(
           ^^^^^^^^^^^^^^^^^^^^^^^^^^^^^
  File "D:\anaconda3\envs\pytorch\Lib\ssl.py", line 1075, in _create
    self.do_handshake()
  File "D:\anaconda3\envs\pytorch\Lib\ssl.py", line 1346, in do_handshake
    self._sslobj.do_handshake()
ConnectionAbortedError: [WinError 10053] 你的主机中的软件中止了一个已建立的连接。

During handling of the above exception, another exception occurred:

Traceback (most recent call last):
  File "D:\anaconda3\envs\pytorch\Lib\site-packages\requests\adapters.py", line 486, in send
    resp = conn.urlopen(
           ^^^^^^^^^^^^^
  File "D:\anaconda3\envs\pytorch\Lib\site-packages\urllib3\connectionpool.py", line 798, in urlopen
    retries = retries.increment(
              ^^^^^^^^^^^^^^^^^^
  File "D:\anaconda3\envs\pytorch\Lib\site-packages\urllib3\util\retry.py", line 592, in increment
    raise MaxRetryError(_pool, url, error or ResponseError(cause))
urllib3.exceptions.MaxRetryError: HTTPSConnectionPool(host='api.bscscan.com', port=443): Max retries exceeded with url: /api?module=contract&action=getsourcecode&address=0x109ea28dbdea5e6ec126fbc8c33845dfe812a300&apikey=M1Z8JTSB37EKZFD56BAGNHTRYYW4IRXIUT (Caused by ProxyError('Cannot connect to proxy.', ConnectionAbortedError(10053, '你的主机中的软件中止了一个已建立的连接。', None, 10053, None)))

During handling of the above exception, another exception occurred:

Traceback (most recent call last):
  File "D:\python\PycharmCodes\RAG\code_process.py", line 164, in <module>
    asyncio.run(handler.process(file))
  File "D:\anaconda3\envs\pytorch\Lib\asyncio\runners.py", line 190, in run
    return runner.run(main)
           ^^^^^^^^^^^^^^^^
  File "D:\anaconda3\envs\pytorch\Lib\asyncio\runners.py", line 118, in run
    return self._loop.run_until_complete(task)
           ^^^^^^^^^^^^^^^^^^^^^^^^^^^^^^^^^^^
  File "D:\anaconda3\envs\pytorch\Lib\asyncio\base_events.py", line 653, in run_until_complete
    return future.result()
           ^^^^^^^^^^^^^^^
  File "D:\python\PycharmCodes\RAG\code_process.py", line 78, in process
    compile_result, dapp_codes = await self._load_compile_result(address_list, _platform)
                                 ^^^^^^^^^^^^^^^^^^^^^^^^^^^^^^^^^^^^^^^^^^^^^^^^^^^^^^^^
  File "D:\python\PycharmCodes\RAG\code_process.py", line 127, in _load_compile_result
    result = requests.get(url)
             ^^^^^^^^^^^^^^^^^
  File "D:\anaconda3\envs\pytorch\Lib\site-packages\requests\api.py", line 73, in get
    return request("get", url, params=params, **kwargs)
           ^^^^^^^^^^^^^^^^^^^^^^^^^^^^^^^^^^^^^^^^^^^^
  File "D:\anaconda3\envs\pytorch\Lib\site-packages\requests\api.py", line 59, in request
    return session.request(method=method, url=url, **kwargs)
           ^^^^^^^^^^^^^^^^^^^^^^^^^^^^^^^^^^^^^^^^^^^^^^^^^
  File "D:\anaconda3\envs\pytorch\Lib\site-packages\requests\sessions.py", line 589, in request
    resp = self.send(prep, **send_kwargs)
           ^^^^^^^^^^^^^^^^^^^^^^^^^^^^^^
  File "D:\anaconda3\envs\pytorch\Lib\site-packages\requests\sessions.py", line 703, in send
    r = adapter.send(request, **kwargs)
        ^^^^^^^^^^^^^^^^^^^^^^^^^^^^^^^
  File "D:\anaconda3\envs\pytorch\Lib\site-packages\requests\adapters.py", line 513, in send
    raise ProxyError(e, request=request)
requests.exceptions.ProxyError: HTTPSConnectionPool(host='api.bscscan.com', port=443): Max retries exceeded with url: /api?module=contract&action=getsourcecode&address=0x109ea28dbdea5e6ec126fbc8c33845dfe812a300&apikey=M1Z8JTSB37EKZFD56BAGNHTRYYW4IRXIUT (Caused by ProxyError('Cannot connect to proxy.', ConnectionAbortedError(10053, '你的主机中的软件中止了一个已建立的连接。', None, 10053, None)))
