
-----------------------------------------
正在处理dapp：PunkProtocol.json~
address list = {'0x032b57fa06c8f6c02be7016fcad81b364708eb68', '0x93ee305e0923c05b45abd47346b8e03da9b3b325', '0x1695ce70da4521cb94dea036e6ebcf1e8a073ee6', '0x00000000b2ff98680adaf8a3e382176bbfc34c8f'}
0x1695ce70da4521cb94dea036e6ebcf1e8a073ee6获取的源代码为空！
0x00000000b2ff98680adaf8a3e382176bbfc34c8f获取的源代码为空！

-----------------------------------------
PunkProtocol.json已经处理完成！

['RevestFinance.json', 'SaddleFinance.json', 'SashimiSwap.json', 'Soda.json', 'SpaceGodzilla.json', 'SushiSwap.json', 'UmbrellaNetwork.json', 'UraniumFinance.json', 'VisorFinance.json', 'WaultFinance.json', 'WildCredit.json', 'XCarnival.json']

-----------------------------------------
正在处理dapp：SaddleFinance.json~
address list = {'0x05383312655856e25b851c15fa856db7e270f0cf', '0x83a30b9c73de15560aa02a18964c45ad7a41d88e', '0x797418a5d9dad50ecc0851e0cc23c61ef4c1b9bf', '0x824dcd7b044d60df2e89b1bb888e66d8bcf41491', '0xa10fca31a2cb432c9ac976779dc947cfdb003ef0', '0xa5bd85ed9fa27ba23bfb702989e7218e44fd4706', '0xeef86c2e49e11345f1a693675df9a38f7d880c8f', '0x7336f819775b1d31ea472681d70ce7a903482191'}
0x83a30b9c73de15560aa02a18964c45ad7a41d88e获取的源代码为空！
0x797418a5d9dad50ecc0851e0cc23c61ef4c1b9bf获取的源代码为空！
0xa10fca31a2cb432c9ac976779dc947cfdb003ef0获取的源代码为空！
0xeef86c2e49e11345f1a693675df9a38f7d880c8f获取的源代码为空！
0x7336f819775b1d31ea472681d70ce7a903482191获取的源代码为空！

-----------------------------------------
SaddleFinance.json已经处理完成！

['RevestFinance.json', 'SashimiSwap.json', 'Soda.json', 'SpaceGodzilla.json', 'SushiSwap.json', 'UmbrellaNetwork.json', 'UraniumFinance.json', 'VisorFinance.json', 'WaultFinance.json', 'WildCredit.json', 'XCarnival.json']

-----------------------------------------
正在处理dapp：Soda.json~


--- 异常信息 ---
Traceback (most recent call last):
  File "D:\anaconda3\envs\pytorch\Lib\site-packages\urllib3\connectionpool.py", line 711, in urlopen
    self._prepare_proxy(conn)
  File "D:\anaconda3\envs\pytorch\Lib\site-packages\urllib3\connectionpool.py", line 1007, in _prepare_proxy
    conn.connect()
  File "D:\anaconda3\envs\pytorch\Lib\site-packages\urllib3\connection.py", line 419, in connect
    self.sock = ssl_wrap_socket(
                ^^^^^^^^^^^^^^^^
  File "D:\anaconda3\envs\pytorch\Lib\site-packages\urllib3\util\ssl_.py", line 449, in ssl_wrap_socket
    ssl_sock = _ssl_wrap_socket_impl(
               ^^^^^^^^^^^^^^^^^^^^^^
  File "D:\anaconda3\envs\pytorch\Lib\site-packages\urllib3\util\ssl_.py", line 493, in _ssl_wrap_socket_impl
    return ssl_context.wrap_socket(sock, server_hostname=server_hostname)
           ^^^^^^^^^^^^^^^^^^^^^^^^^^^^^^^^^^^^^^^^^^^^^^^^^^^^^^^^^^^^^^
  File "D:\anaconda3\envs\pytorch\Lib\ssl.py", line 517, in wrap_socket
    return self.sslsocket_class._create(
           ^^^^^^^^^^^^^^^^^^^^^^^^^^^^^
  File "D:\anaconda3\envs\pytorch\Lib\ssl.py", line 1075, in _create
    self.do_handshake()
  File "D:\anaconda3\envs\pytorch\Lib\ssl.py", line 1346, in do_handshake
    self._sslobj.do_handshake()
ConnectionAbortedError: [WinError 10053] 你的主机中的软件中止了一个已建立的连接。

During handling of the above exception, another exception occurred:

Traceback (most recent call last):
  File "D:\anaconda3\envs\pytorch\Lib\site-packages\requests\adapters.py", line 486, in send
    resp = conn.urlopen(
           ^^^^^^^^^^^^^
  File "D:\anaconda3\envs\pytorch\Lib\site-packages\urllib3\connectionpool.py", line 798, in urlopen
    retries = retries.increment(
              ^^^^^^^^^^^^^^^^^^
  File "D:\anaconda3\envs\pytorch\Lib\site-packages\urllib3\util\retry.py", line 592, in increment
    raise MaxRetryError(_pool, url, error or ResponseError(cause))
urllib3.exceptions.MaxRetryError: HTTPSConnectionPool(host='api.etherscan.io', port=443): Max retries exceeded with url: /api?module=proxy&action=eth_getTransactionReceipt&txhash=0xfadf4503cc35848d6aac657c648b573c0d02ef551352988b3daf772547f55866&apikey=4QP6SY9V7XXDJDEJBGC1NAI3KXRIU5CDEE (Caused by ProxyError('Cannot connect to proxy.', ConnectionAbortedError(10053, '你的主机中的软件中止了一个已建立的连接。', None, 10053, None)))

During handling of the above exception, another exception occurred:

Traceback (most recent call last):
  File "D:\python\PycharmCodes\RAG\code_process.py", line 164, in <module>
    asyncio.run(handler.process(file))
  File "D:\anaconda3\envs\pytorch\Lib\asyncio\runners.py", line 190, in run
    return runner.run(main)
           ^^^^^^^^^^^^^^^^
  File "D:\anaconda3\envs\pytorch\Lib\asyncio\runners.py", line 118, in run
    return self._loop.run_until_complete(task)
           ^^^^^^^^^^^^^^^^^^^^^^^^^^^^^^^^^^^
  File "D:\anaconda3\envs\pytorch\Lib\asyncio\base_events.py", line 653, in run_until_complete
    return future.result()
           ^^^^^^^^^^^^^^^
  File "D:\python\PycharmCodes\RAG\code_process.py", line 67, in process
    address = get_contract_address_from_tx(_hash, _platform)
              ^^^^^^^^^^^^^^^^^^^^^^^^^^^^^^^^^^^^^^^^^^^^^^
  File "D:\python\PycharmCodes\RAG\get_source_code.py", line 27, in get_contract_address_from_tx
    response = requests.get(url)
               ^^^^^^^^^^^^^^^^^
  File "D:\anaconda3\envs\pytorch\Lib\site-packages\requests\api.py", line 73, in get
    return request("get", url, params=params, **kwargs)
           ^^^^^^^^^^^^^^^^^^^^^^^^^^^^^^^^^^^^^^^^^^^^
  File "D:\anaconda3\envs\pytorch\Lib\site-packages\requests\api.py", line 59, in request
    return session.request(method=method, url=url, **kwargs)
           ^^^^^^^^^^^^^^^^^^^^^^^^^^^^^^^^^^^^^^^^^^^^^^^^^
  File "D:\anaconda3\envs\pytorch\Lib\site-packages\requests\sessions.py", line 589, in request
    resp = self.send(prep, **send_kwargs)
           ^^^^^^^^^^^^^^^^^^^^^^^^^^^^^^
  File "D:\anaconda3\envs\pytorch\Lib\site-packages\requests\sessions.py", line 703, in send
    r = adapter.send(request, **kwargs)
        ^^^^^^^^^^^^^^^^^^^^^^^^^^^^^^^
  File "D:\anaconda3\envs\pytorch\Lib\site-packages\requests\adapters.py", line 513, in send
    raise ProxyError(e, request=request)
requests.exceptions.ProxyError: HTTPSConnectionPool(host='api.etherscan.io', port=443): Max retries exceeded with url: /api?module=proxy&action=eth_getTransactionReceipt&txhash=0xfadf4503cc35848d6aac657c648b573c0d02ef551352988b3daf772547f55866&apikey=4QP6SY9V7XXDJDEJBGC1NAI3KXRIU5CDEE (Caused by ProxyError('Cannot connect to proxy.', ConnectionAbortedError(10053, '你的主机中的软件中止了一个已建立的连接。', None, 10053, None)))
