
-----------------------------------------
正在处理dapp：SashimiSwap.json~
address list = {'0xa57bd00134b2850b2a1c55860c9e9ea100fdd6cf', '0x2ccc076d1de2d88209f491c679fa5bde870c384a', '0xe4fe6a45f354e845f954cddee6084603cedb9410', '0x70526cc7a6d6320b44122ea9d2d07670accc85a1', '0x0000000000007f150bd6f54c40a34d7c3d5e9f56'}
0xa57bd00134b2850b2a1c55860c9e9ea100fdd6cf获取的源代码为空！
0x2ccc076d1de2d88209f491c679fa5bde870c384a获取的源代码为空！
0xe4fe6a45f354e845f954cddee6084603cedb9410获取的源代码为空！
0x70526cc7a6d6320b44122ea9d2d07670accc85a1获取的源代码为空！
0x0000000000007f150bd6f54c40a34d7c3d5e9f56获取的源代码为空！

-----------------------------------------
SashimiSwap.json已经处理完成！

['Soda.json', 'SpaceGodzilla.json', 'SushiSwap.json', 'UmbrellaNetwork.json', 'UraniumFinance.json', 'VisorFinance.json', 'WaultFinance.json', 'WildCredit.json', 'XCarnival.json']

-----------------------------------------
正在处理dapp：SpaceGodzilla.json~
address list = {'0x3d817ea746edd02c088c4df47c0ece0bd28dcd72', '0x2287c04a15bb11ad1358ba5702c1c95e2d13a5e0'}
0x3d817ea746edd02c088c4df47c0ece0bd28dcd72获取的源代码为空！
0x2287c04a15bb11ad1358ba5702c1c95e2d13a5e0获取的源代码为空！

-----------------------------------------
SpaceGodzilla.json已经处理完成！

['Soda.json', 'SushiSwap.json', 'UmbrellaNetwork.json', 'UraniumFinance.json', 'VisorFinance.json', 'WaultFinance.json', 'WildCredit.json', 'XCarnival.json']

-----------------------------------------
正在处理dapp：UmbrellaNetwork.json~
address list = {'0xb3fb1d01b07a706736ca175f827e4f56021b85de', '0x89767960b76b009416bc7ff4a4b79051eed0a9ee'}

故障函数！
0x89767960b76b009416bc7ff4a4b79051eed0a9ee获取的源代码为空！

-----------------------------------------
UmbrellaNetwork.json已经处理完成！

['Soda.json', 'SushiSwap.json', 'UraniumFinance.json', 'VisorFinance.json', 'WaultFinance.json', 'WildCredit.json', 'XCarnival.json']

-----------------------------------------
正在处理dapp：VisorFinance.json~
address list = {'0x10c509aa9ab291c76c45414e7cdbd375e1d5ace8', '0xc9f27a50f82571c1c8423a42970613b8dbda14ef'}
0x10c509aa9ab291c76c45414e7cdbd375e1d5ace8获取的源代码为空！

故障函数！

-----------------------------------------
VisorFinance.json已经处理完成！

['Soda.json', 'SushiSwap.json', 'UraniumFinance.json', 'WaultFinance.json', 'WildCredit.json', 'XCarnival.json']

-----------------------------------------
正在处理dapp：WildCredit.json~


--- 异常信息 ---
Traceback (most recent call last):
  File "D:\anaconda3\envs\pytorch\Lib\site-packages\urllib3\connectionpool.py", line 711, in urlopen
    self._prepare_proxy(conn)
  File "D:\anaconda3\envs\pytorch\Lib\site-packages\urllib3\connectionpool.py", line 1007, in _prepare_proxy
    conn.connect()
  File "D:\anaconda3\envs\pytorch\Lib\site-packages\urllib3\connection.py", line 419, in connect
    self.sock = ssl_wrap_socket(
                ^^^^^^^^^^^^^^^^
  File "D:\anaconda3\envs\pytorch\Lib\site-packages\urllib3\util\ssl_.py", line 449, in ssl_wrap_socket
    ssl_sock = _ssl_wrap_socket_impl(
               ^^^^^^^^^^^^^^^^^^^^^^
  File "D:\anaconda3\envs\pytorch\Lib\site-packages\urllib3\util\ssl_.py", line 493, in _ssl_wrap_socket_impl
    return ssl_context.wrap_socket(sock, server_hostname=server_hostname)
           ^^^^^^^^^^^^^^^^^^^^^^^^^^^^^^^^^^^^^^^^^^^^^^^^^^^^^^^^^^^^^^
  File "D:\anaconda3\envs\pytorch\Lib\ssl.py", line 517, in wrap_socket
    return self.sslsocket_class._create(
           ^^^^^^^^^^^^^^^^^^^^^^^^^^^^^
  File "D:\anaconda3\envs\pytorch\Lib\ssl.py", line 1075, in _create
    self.do_handshake()
  File "D:\anaconda3\envs\pytorch\Lib\ssl.py", line 1346, in do_handshake
    self._sslobj.do_handshake()
ConnectionAbortedError: [WinError 10053] 你的主机中的软件中止了一个已建立的连接。

During handling of the above exception, another exception occurred:

Traceback (most recent call last):
  File "D:\anaconda3\envs\pytorch\Lib\site-packages\requests\adapters.py", line 486, in send
    resp = conn.urlopen(
           ^^^^^^^^^^^^^
  File "D:\anaconda3\envs\pytorch\Lib\site-packages\urllib3\connectionpool.py", line 798, in urlopen
    retries = retries.increment(
              ^^^^^^^^^^^^^^^^^^
  File "D:\anaconda3\envs\pytorch\Lib\site-packages\urllib3\util\retry.py", line 592, in increment
    raise MaxRetryError(_pool, url, error or ResponseError(cause))
urllib3.exceptions.MaxRetryError: HTTPSConnectionPool(host='api.etherscan.io', port=443): Max retries exceeded with url: /api?module=proxy&action=eth_getTransactionReceipt&txhash=0xb36e3687a89bbbed54387983856542c6ab1d82558eee8bb8b84375e2569bd1e8&apikey=4QP6SY9V7XXDJDEJBGC1NAI3KXRIU5CDEE (Caused by ProxyError('Cannot connect to proxy.', ConnectionAbortedError(10053, '你的主机中的软件中止了一个已建立的连接。', None, 10053, None)))

During handling of the above exception, another exception occurred:

Traceback (most recent call last):
  File "D:\python\PycharmCodes\RAG\code_process.py", line 164, in <module>
    asyncio.run(handler.process(file))
  File "D:\anaconda3\envs\pytorch\Lib\asyncio\runners.py", line 190, in run
    return runner.run(main)
           ^^^^^^^^^^^^^^^^
  File "D:\anaconda3\envs\pytorch\Lib\asyncio\runners.py", line 118, in run
    return self._loop.run_until_complete(task)
           ^^^^^^^^^^^^^^^^^^^^^^^^^^^^^^^^^^^
  File "D:\anaconda3\envs\pytorch\Lib\asyncio\base_events.py", line 653, in run_until_complete
    return future.result()
           ^^^^^^^^^^^^^^^
  File "D:\python\PycharmCodes\RAG\code_process.py", line 67, in process
    address = get_contract_address_from_tx(_hash, _platform)
              ^^^^^^^^^^^^^^^^^^^^^^^^^^^^^^^^^^^^^^^^^^^^^^
  File "D:\python\PycharmCodes\RAG\get_source_code.py", line 27, in get_contract_address_from_tx
    response = requests.get(url)
               ^^^^^^^^^^^^^^^^^
  File "D:\anaconda3\envs\pytorch\Lib\site-packages\requests\api.py", line 73, in get
    return request("get", url, params=params, **kwargs)
           ^^^^^^^^^^^^^^^^^^^^^^^^^^^^^^^^^^^^^^^^^^^^
  File "D:\anaconda3\envs\pytorch\Lib\site-packages\requests\api.py", line 59, in request
    return session.request(method=method, url=url, **kwargs)
           ^^^^^^^^^^^^^^^^^^^^^^^^^^^^^^^^^^^^^^^^^^^^^^^^^
  File "D:\anaconda3\envs\pytorch\Lib\site-packages\requests\sessions.py", line 589, in request
    resp = self.send(prep, **send_kwargs)
           ^^^^^^^^^^^^^^^^^^^^^^^^^^^^^^
  File "D:\anaconda3\envs\pytorch\Lib\site-packages\requests\sessions.py", line 703, in send
    r = adapter.send(request, **kwargs)
        ^^^^^^^^^^^^^^^^^^^^^^^^^^^^^^^
  File "D:\anaconda3\envs\pytorch\Lib\site-packages\requests\adapters.py", line 513, in send
    raise ProxyError(e, request=request)
requests.exceptions.ProxyError: HTTPSConnectionPool(host='api.etherscan.io', port=443): Max retries exceeded with url: /api?module=proxy&action=eth_getTransactionReceipt&txhash=0xb36e3687a89bbbed54387983856542c6ab1d82558eee8bb8b84375e2569bd1e8&apikey=4QP6SY9V7XXDJDEJBGC1NAI3KXRIU5CDEE (Caused by ProxyError('Cannot connect to proxy.', ConnectionAbortedError(10053, '你的主机中的软件中止了一个已建立的连接。', None, 10053, None)))
